Workbook

Sheet Export Summary
B3: This document was exported from Numbers. Each table was converted to an Excel worksheet. All other objects on each Numbers sheet were placed on separate worksheets. Please be aware that formula calculations may differ in Excel.
B7: Numbers Sheet Name | C7: Numbers Table Name | D7: Excel Worksheet Name
B9: Sheet 1
C10: 12V 10Ah LFP Discharge Curve @ 0.1C | D10: Sheet 1 - 12V 10Ah LFP Discharg
B11: Sheet 1-1
C12: 12V 10Ah LFP Discharge Curve @ 0.1C | D12: Sheet 1-1 - 12V 10Ah LFP Discha
B13: Solar Panel Comparisons
C14: Solar Panel Comparisons (Fixed point vs. solar tracking) | D14: Solar Panel Comparisons - Solar
B15: Riemann Sum
C16: Midpoint Riemann Sums ( | D16: Riemann Sum - Midpoint Riemann

Sheet Sheet 1 - 12V 10Ah LFP Discharg
A1: 12V 10Ah LFP Discharge Curve @ 0.1C
C2: 07-14-2026 (Ah) | D2: Voltage (V) | E2: 07-16-2026 (Ah) | F2: Voltage (V) | G2: 07-17-2026 (Ah) | H2: Voltage (V)
C3: 0.002 | D3: 13.01 | E3: 0.074 | F3: 12.94 | G3: 0.035 | H3: 12.94
C4: 0.003 | D4: 13 | E4: 0.848 | F4: 12.93 | G4: 0.06 | H4: 12.93
C5: 0.005 | D5: 12.99 | E5: 1.764 | F5: 12.92 | G5: 0.075 | H5: 12.92
C6: 0.008 | D6: 12.98 | E6: 2.378 | F6: 12.91 | G6: 0.104 | H6: 12.91
C7: 0.011 | D7: 12.97 | E7: 2.776 | F7: 12.9 | G7: 0.127 | H7: 12.9
C8: 0.017 | D8: 12.96 | E8: 3.067 | F8: 12.89 | G8: 0.164 | H8: 12.89
C9: 0.021 | D9: 12.95 | E9: 3.29 | F9: 12.88 | G9: 0.185 | H9: 12.88
C10: 0.029 | D10: 12.94 | E10: 3.453 | F10: 12.87 | G10: 0.22 | H10: 12.87
C11: 0.053 | D11: 12.93 | E11: 3.572 | F11: 12.86 | G11: 0.264 | H11: 12.86
C12: 0.384 | D12: 12.92 | E12: 3.718 | F12: 12.85 | G12: 0.311 | H12: 12.85
C13: 0.484 | D13: 12.91 | E13: 3.795 | F13: 12.84 | G13: 0.382 | H13: 12.84
C14: 0.537 | D14: 12.9 | E14: 3.941 | F14: 12.83 | G14: 0.504 | H14: 12.83
... C22: 0.914 | D22: 12.82 | E22: 6.318 | F22: 12.75 | G22: 3.827 | H22: 12.75
C23: 0.998 | D23: 12.81 | E23: 6.919 | F23: 12.74
C24: 1.217 | D24: 12.8 | E24: 7.266 | F24: 12.73
C25: 1.359 | D25: 12.79 | E25: 7.474 | F25: 12.72
C26: 1.777 | D26: 12.78 | E26: 7.742 | F26: 12.71
C27: 2.66 | D27: 12.77 | E27: 7.923 | F27: 12.7
C28: 3.451 | D28: 12.76 | E28: 8.026 | F28: 12.69
C29: 3.822 | D29: 12.75 | E29: 8.156 | F29: 12.68
C30: 4.162 | D30: 12.74 | E30: 8.255 | F30: 12.67
C31: 4.328 | D31: 12.73 | E31: 8.344 | F31: 12.66
C32: 4.515 | D32: 12.72 | E32: 8.452 | F32: 12.65
C33: 4.627 | D33: 12.71 | E33: 8.551 | F33: 12.64
C34: 4.725 | D34: 12.7 | E34: 8.642 | F34: 12.63
... C97: 7.921 | D97: 12.07 | E97: 11.32 | F97: 12
C98: 7.929 | D98: 12.06
C99: 7.936 | D99: 12.05
C100: 7.946 | D100: 12.04
C101: 7.953 | D101: 12.03
C102: 7.961 | D102: 12.02
C103: 7.969 | D103: 12.01
B108: 07/16/26 re-test
C109: 0.074 | D109: 12.94
C110: 0.848 | D110: 12.93
C111: 1.764 | D111: 12.92
C112: 2.378 | D112: 12.91
C113: 2.776 | D113: 12.9
...

Sheet Sheet 1-1 - 12V 10Ah LFP Discha
A1: 12V 10Ah LFP Discharge Curve @ 0.1C
C2: Capacity (Ah) | D2: Voltage (V) | E2: Capacity (Ah) | F2: Voltage (V)
C3: 3.322 | D3: 13.01 | E3: 0.074 | F3: 12.94 | G3: {=C3+3.32} -> 6.642
C4: 3.323 | D4: 13 | E4: 0.848 | F4: 12.93 | G4: {=C4+3.32} -> 6.643
C5: 3.325 | D5: 12.99 | E5: 1.764 | F5: 12.92 | G5: {=C5+3.32} -> 6.645
C6: 3.328 | D6: 12.98 | E6: 2.378 | F6: 12.91 | G6: {=C6+3.32} -> 6.648
C7: 3.331 | D7: 12.97 | E7: 2.776 | F7: 12.9 | G7: {=C7+3.32} -> 6.651
C8: 3.337 | D8: 12.96 | E8: 3.067 | F8: 12.89 | G8: {=C8+3.32} -> 6.657
C9: 3.341 | D9: 12.95 | E9: 3.29 | F9: 12.88 | G9: {=C9+3.32} -> 6.661
C10: 3.349 | D10: 12.94 | E10: 3.453 | F10: 12.87 | G10: {=C10+3.32} -> 6.669
C11: 3.373 | D11: 12.93 | E11: 3.572 | F11: 12.86 | G11: {=C11+3.32} -> 6.693
C12: 3.704 | D12: 12.92 | E12: 3.718 | F12: 12.85 | G12: {=C12+3.32} -> 7.024
C13: 3.804 | D13: 12.91 | E13: 3.795 | F13: 12.84 | G13: {=C13+3.32} -> 7.124
C14: 3.857 | D14: 12.9 | E14: 3.941 | F14: 12.83 | G14: {=C14+3.32} -> 7.177
... C97: 11.241 | D97: 12.07 | E97: 11.32 | F97: 12 | G97: {=C97+3.32} -> 14.561
C98: 11.249 | D98: 12.06 | G98: {=C98+3.32} -> 14.569
C99: 11.256 | D99: 12.05 | G99: {=C99+3.32} -> 14.576
C100: 11.266 | D100: 12.04 | G100: {=C100+3.32} -> 14.586
C101: 11.273 | D101: 12.03 | G101: {=C101+3.32} -> 14.593
C102: 11.281 | D102: 12.02 | G102: {=C102+3.32} -> 14.601
C103: 11.289 | D103: 12.01 | G103: {=C103+3.32} -> 14.609
B108: 07/16/26 re-test
C109: 0.074 | D109: 12.94
C110: 0.848 | D110: 12.93
C111: 1.764 | D111: 12.92
C112: 2.378 | D112: 12.91
C113: 2.776 | D113: 12.9
C114: 3.067 | D114: 12.89
C115: 3.29 | D115: 12.88
C116: 3.453 | D116: 12.87
C117: 3.572 | D117: 12.86
C118: 3.718 | D118: 12.85
C119: 3.795 | D119: 12.84
C120: 3.941 | D120: 12.83
... C203: 11.32 | D203: 12

Sheet Solar Panel Comparisons - Solar
A1: Solar Panel Comparisons (Fixed point vs. solar tracking)
B2: Time of Day | C2: Fixed (A) | D2: Time of Day | E2: Tracker On (A)
B3: 46225.281 | C3: 0.72 | D3: 46225.281 | E3: 0.4 | F3: =0.69-E3 -> 0.29
B4: 46225.302 | C4: 0.59 | E4: 0.19 | F4: =0.69-E4 -> 0.5 | G4: =(F3+F4)/4-'Riemann Sum - Midpoint Riemann '!I4 -> 0.1725
B5: 46225.323 | C5: 0.47 | E5: 0.68 | F5: =1.3-E5 -> 0.62 | G5: =(F4+F5)/4-'Riemann Sum - Midpoint Riemann '!I5 -> 0.2
B6: 46225.344 | C6: 0.35 | E6: 0.58 | F6: =1.3-E6 -> 0.72 | G6: =(F5+F6)/4-'Riemann Sum - Midpoint Riemann '!I6 -> 0.195
B7: 46225.365 | C7: 0.24 | E7: 0.56 | F7: =1.3-E7 -> 0.74 | G7: =(F6+F7)/4-'Riemann Sum - Midpoint Riemann '!I7 -> 0.1675
B8: 46225.385 | C8: 0.12 | E8: 0.52 | F8: =1.3-E8 -> 0.78 | G8: =(F7+F8)/4-'Riemann Sum - Midpoint Riemann '!I8 -> 0.125
B9: 46225.385 | C9: 0.71
B10: 46225.406 | C10: 0.64 | E10: 0.49 | F10: =1.3-E10 -> 0.81 | G10: =(F8+F10)/4-'Riemann Sum - Midpoint Riemann '!I10 -> 0.085
B11: 46225.427 | C11: 0.54 | E11: 0.46 | F11: =1.3-E11 -> 0.84 | G11: =(F10+F11)/4-'Riemann Sum - Midpoint Riemann '!I11 -> 0.0575
B12: 46225.448 | C12: 0.47 | E12: 0.43 | F12: =1.3-E12 -> 0.87 | G12: =(F11+F12)/4-'Riemann Sum - Midpoint Riemann '!I12 -> 0.03
B13: 46225.469 | C13: 0.4 | E13: 0.42 | F13: =1.3-E13 -> 0.88 | G13: =(F12+F13)/4-'Riemann Sum - Midpoint Riemann '!I13 -> 0.005
B14: 46225.49 | C14: 0.36 | E14: 0.4 | F14: =1.3-E14 -> 0.9 | G14: =(F13+F14)/4-'Riemann Sum - Midpoint Riemann '!I14 -> -0.015
B15: 46225.51 | C15: 0.34 | E15: 0.4 | F15: =1.3-E15 -> 0.9 | G15: =(F14+F15)/4-'Riemann Sum - Midpoint Riemann '!I15 -> -0.025
B16: 46225.531 | C16: 0.32 | E16: 0.39 | F16: =1.3-E16 -> 0.91 | G16: =(F15+F16)/4-'Riemann Sum - Midpoint Riemann '!I16 -> -0.0325
B17: 46225.552 | C17: 0.33 | E17: 0.39 | F17: =1.3-E17 -> 0.91 | G17: =(F16+F17)/4-'Riemann Sum - Midpoint Riemann '!I17 -> -0.0325
B18: 46225.573 | C18: 0.34 | E18: 0.4 | F18: =1.3-E18 -> 0.9 | G18: =(F17+F18)/4-'Riemann Sum - Midpoint Riemann '!I18 -> -0.03
B19: 46225.594 | C19: 0.38 | E19: 0.4 | F19: =1.3-E19 -> 0.9 | G19: =(F18+F19)/4-'Riemann Sum - Midpoint Riemann '!I19 -> -0.02
B20: 46225.615 | C20: 0.42 | E20: 0.42 | F20: =1.3-E20 -> 0.88 | G20: =(F19+F20)/4-'Riemann Sum - Midpoint Riemann '!I20 -> -0.005
B21: 46225.635 | C21: 0.47 | E21: 0.44 | F21: =1.3-E21 -> 0.86 | G21: =(F20+F21)/4-'Riemann Sum - Midpoint Riemann '!I21 -> 0.0075
B22: 46225.656 | C22: 0.55 | E22: 0.46 | F22: =1.3-E22 -> 0.84 | G22: =(F21+F22)/4-'Riemann Sum - Midpoint Riemann '!I22 -> 0.03
... B24: 46225.698 | C24: 0.75 | E24: 0.52 | F24: =1.3-E24 -> 0.78 | G24: =(F23+F24)/4-'Riemann Sum - Midpoint Riemann '!I24 -> 0.1
B25: 46225.698 | C25: 0.1
B26: 46225.719 | C26: 0.2 | E26: 0.56 | F26: =1.3-E26 -> 0.74 | G26: =(F24+F26)/4-'Riemann Sum - Midpoint Riemann '!I26 -> 0.11
B27: 46225.74 | C27: 0.32 | E27: 0.55 | F27: =1.3-E27 -> 0.75 | G27: =(F26+F27)/4-'Riemann Sum - Midpoint Riemann '!I27 -> 0.1575
B28: 46225.76 | C28: 0.45 | E28: 0.03 | F28: =0.69-E28 -> 0.66 | G28: =(F27+F28)/4-'Riemann Sum - Midpoint Riemann '!I28 -> 0.2
A29: Energy (Ah) | B29: 0.78125 | C29: 4.9025
A30: Current w/o light | B30: 0.80208333 | C30: 0.69
A31: Current w/ light | C31: 1.3 | G31: =SUM(G4:G30) -> 1.5475
A32: Average | C32: {=AVERAGE(C3:C28)} -> 0.43192308 | G32: =G31+0.65*12/9 -> 2.4141667
G33: =G32/'Riemann Sum - Midpoint Riemann '!I31 -> 0.3170278

Sheet Riemann Sum - Midpoint Riemann 
A1: Midpoint Riemann Sums (
A2: Time of Day | B2: Fixed (A) | C2: Average * Time | E2: Interval (hr) | F2: Light off (Ah) | G2: Light on (Ah) | H2: Current by Solar | I2: Average * Time
A3: 46225.281 | B3: 0.72 | E3: 0.5 | F3: 0.69 | G3: 1.3 | H3: 0
A4: 46225.302 | B4: 0.59 | C4: {=(B4+B3)/2*$E$3} -> 0.3275 | H4: {=-B4+$F$3} -> 0.1 | I4: {=(H4+H3)/2*$E$3} -> 0.025
A5: 46225.323 | B5: 0.47 | C5: {=(B5+B4)/2*$E$3} -> 0.265 | H5: {=-B5+$F$3} -> 0.22 | I5: {=(H5+H4)/2*$E$3} -> 0.08
A6: 46225.344 | B6: 0.35 | C6: {=(B6+B5)/2*$E$3} -> 0.205 | H6: {=-B6+$F$3} -> 0.34 | I6: {=(H6+H5)/2*$E$3} -> 0.14
A7: 46225.365 | B7: 0.24 | C7: {=(B7+B6)/2*$E$3} -> 0.1475 | H7: {=-B7+$F$3} -> 0.45 | I7: {=(H7+H6)/2*$E$3} -> 0.1975
A8: 46225.385 | B8: 0.12 | C8: {=(B8+B7)/2*$E$3} -> 0.09 | H8: {=-B8+$F$3} -> 0.57 | I8: {=(H8+H7)/2*$E$3} -> 0.255
A9: 46225.385 | B9: 0.71 | H9: {=-B9+$G$3} -> 0.59
A10: 46225.406 | B10: 0.64 | C10: {=(B10+B9)/2*$E$3} -> 0.3375 | H10: {=-B10+$G$3} -> 0.66 | I10: {=(H10+H9)/2*$E$3} -> 0.3125
A11: 46225.427 | B11: 0.54 | C11: {=(B11+B10)/2*$E$3} -> 0.295 | H11: {=-B11+$G$3} -> 0.76 | I11: {=(H11+H10)/2*$E$3} -> 0.355
A12: 46225.448 | B12: 0.47 | C12: {=(B12+B11)/2*$E$3} -> 0.2525 | H12: {=-B12+$G$3} -> 0.83 | I12: {=(H12+H11)/2*$E$3} -> 0.3975
A13: 46225.469 | B13: 0.4 | C13: {=(B13+B12)/2*$E$3} -> 0.2175 | H13: {=-B13+$G$3} -> 0.9 | I13: {=(H13+H12)/2*$E$3} -> 0.4325
A14: 46225.49 | B14: 0.36 | C14: {=(B14+B13)/2*$E$3} -> 0.19 | H14: {=-B14+$G$3} -> 0.94 | I14: {=(H14+H13)/2*$E$3} -> 0.46
A15: 46225.51 | B15: 0.34 | C15: {=(B15+B14)/2*$E$3} -> 0.175 | H15: {=-B15+$G$3} -> 0.96 | I15: {=(H15+H14)/2*$E$3} -> 0.475
A16: 46225.531 | B16: 0.32 | C16: {=(B16+B15)/2*$E$3} -> 0.165 | H16: {=-B16+$G$3} -> 0.98 | I16: {=(H16+H15)/2*$E$3} -> 0.485
A17: 46225.552 | B17: 0.33 | C17: {=(B17+B16)/2*$E$3} -> 0.1625 | H17: {=-B17+$G$3} -> 0.97 | I17: {=(H17+H16)/2*$E$3} -> 0.4875
A18: 46225.573 | B18: 0.34 | C18: {=(B18+B17)/2*$E$3} -> 0.1675 | H18: {=-B18+$G$3} -> 0.96 | I18: {=(H18+H17)/2*$E$3} -> 0.4825
A19: 46225.594 | B19: 0.38 | C19: {=(B19+B18)/2*$E$3} -> 0.18 | H19: {=-B19+$G$3} -> 0.92 | I19: {=(H19+H18)/2*$E$3} -> 0.47
A20: 46225.615 | B20: 0.42 | C20: {=(B20+B19)/2*$E$3} -> 0.2 | H20: {=-B20+$G$3} -> 0.88 | I20: {=(H20+H19)/2*$E$3} -> 0.45
A21: 46225.635 | B21: 0.47 | C21: {=(B21+B20)/2*$E$3} -> 0.2225 | H21: {=-B21+$G$3} -> 0.83 | I21: {=(H21+H20)/2*$E$3} -> 0.4275
... A24: 46225.698 | B24: 0.75 | C24: {=(B24+B23)/2*$E$3} -> 0.35 | H24: {=-B24+$G$3} -> 0.55 | I24: {=(H24+H23)/2*$E$3} -> 0.3
A25: 46225.698 | B25: 0.1 | H25: {=-B25+$F$3} -> 0.59
A26: 46225.719 | B26: 0.2 | C26: {=(B26+B25)/2*$E$3} -> 0.075 | H26: {=-B26+$F$3} -> 0.49 | I26: {=(H26+H25)/2*$E$3} -> 0.27
A27: 46225.74 | B27: 0.32 | C27: {=(B27+B26)/2*$E$3} -> 0.13 | H27: {=-B27+$F$3} -> 0.37 | I27: {=(H27+H26)/2*$E$3} -> 0.215
A28: 46225.76 | B28: 0.45 | C28: {=(B28+B27)/2*$E$3} -> 0.1925 | H28: {=-B28+$F$3} -> 0.24 | I28: {=(H28+H27)/2*$E$3} -> 0.1525
A29: 0.78125
A30: 0.80208333
C31: {=SUM(C3:C28)} -> 4.9025 | I31: {=SUM(I3:I28)} -> 7.615

Sheet Sheet1
A1: Time of Day | B1: Fixed at 34 Degrees | C1: Single Axis | D1: Dual Axis
A2: 46225.281 | B2: 0.005 | C2: 0.23 | D2: 0.35
A3: 46225.302 | B3: 0.03 | C3: 0.5 | D3: 0.55
A4: 46225.323 | B4: 0.13 | C4: 0.67 | D4: 0.74 | E4: 0.53
A5: 46225.344 | B5: 0.23 | C5: 0.77 | D5: 0.84 | E5: 0.65
A6: 46225.365 | B6: 0.37 | C6: 0.85 | D6: 0.86 | E6: 0.75
A7: 46225.385 | B7: 0.49 | C7: 0.89 | D7: 0.9 | E7: 0.85
A8: 46225.406 | B8: 0.6 | C8: 0.94 | D8: 0.93 | E8: 0.87
A9: 46225.427 | B9: 0.7 | C9: 0.96 | D9: 0.96 | E9: 0.92
A10: 46225.448 | B10: 0.8 | C10: 0.98 | D10: 0.99 | E10: 0.95
A11: 46225.469 | B11: 0.87 | C11: 1 | D11: 1 | E11: 0.97
A12: 46225.49 | B12: 0.93 | C12: 1 | D12: 1.02 | E12: 1
A13: 46225.51 | B13: 0.98 | C13: 0.99 | D13: 1.03 | E13: 1.02
A14: 46225.531 | B14: 0.99 | C14: 0.98 | D14: 1.03 | E14: 1.01
A15: 46225.552 | B15: 0.99 | C15: 0.99 | D15: 1.03 | E15: 1.02
... A25: 46225.76 | B25: 0.16 | C25: 0.74 | D25: 0.78 | E25: 0.7
A26: 0.78125 | B26: 0.05 | C26: 0.6 | D26: 0.62
A27: 0.80208333 | B27: 0.01 | C27: 0.3 | D27: 0.41
A29: AVERAGES | B29: =(B3+B2)/2*0.5 -> 0.00875 | C29: =(C3+C2)/2*0.5 -> 0.1825 | D29: =(D3+D2)/2*0.5 -> 0.225
B30: =(B4+B3)/2*0.5 -> 0.04 | C30: =(C4+C3)/2*0.5 -> 0.2925 | D30: =(D4+D3)/2*0.5 -> 0.3225
B31: =(B5+B4)/2*0.5 -> 0.09 | C31: =(C5+C4)/2*0.5 -> 0.36 | D31: =(D5+D4)/2*0.5 -> 0.395
B32: =(B6+B5)/2*0.5 -> 0.15 | C32: =(C6+C5)/2*0.5 -> 0.405 | D32: =(D6+D5)/2*0.5 -> 0.425
B33: =(B7+B6)/2*0.5 -> 0.215 | C33: =(C7+C6)/2*0.5 -> 0.435 | D33: =(D7+D6)/2*0.5 -> 0.44
B34: =(B8+B7)/2*0.5 -> 0.2725 | C34: =(C8+C7)/2*0.5 -> 0.4575 | D34: =(D8+D7)/2*0.5 -> 0.4575
B35: =(B9+B8)/2*0.5 -> 0.325 | C35: =(C9+C8)/2*0.5 -> 0.475 | D35: =(D9+D8)/2*0.5 -> 0.4725
B36: =(B10+B9)/2*0.5 -> 0.375 | C36: =(C10+C9)/2*0.5 -> 0.485 | D36: =(D10+D9)/2*0.5 -> 0.4875
B37: =(B11+B10)/2*0.5 -> 0.4175 | C37: =(C11+C10)/2*0.5 -> 0.495 | D37: =(D11+D10)/2*0.5 -> 0.4975
B38: =(B12+B11)/2*0.5 -> 0.45 | C38: =(C12+C11)/2*0.5 -> 0.5 | D38: =(D12+D11)/2*0.5 -> 0.505
B39: =(B13+B12)/2*0.5 -> 0.4775 | C39: =(C13+C12)/2*0.5 -> 0.4975 | D39: =(D13+D12)/2*0.5 -> 0.5125
B40: =(B14+B13)/2*0.5 -> 0.4925 | C40: =(C14+C13)/2*0.5 -> 0.4925 | D40: =(D14+D13)/2*0.5 -> 0.515
B41: =(B15+B14)/2*0.5 -> 0.495 | C41: =(C15+C14)/2*0.5 -> 0.4925 | D41: =(D15+D14)/2*0.5 -> 0.515
... B53: =(B27+B26)/2*0.5 -> 0.015 | C53: =(C27+C26)/2*0.5 -> 0.225 | D53: =(D27+D26)/2*0.5 -> 0.2575
A54: SUM | B54: =SUM(B29:B53) -> 7.24875 | C54: =SUM(C29:C53) -> 10.7925 | D54: =SUM(D29:D53) -> 11.055
